Workbook

Sheet 📋 Raw Data
A1: # | B1: الشهر | C1: اليوم | D1: الوردية | E1: الفرع | F1: التصنيف | G1: الصنف | H1: الكمية المباعة | I1: سعر الوحدة (ج.م) | J1: إجمالي المبيعات (ج.م) | K1: تكلفة البضاعة (ج.م) | L1: هامش الربح (ج.م) | M1: نسبة الربح % | N1: تقييم الخدمة
A2: 1 | B2: يناير | C2: السبت | D2: صباحي | E2: فرع الزمالك | F2: حلويات | G2: بسبوسة | H2: 34 | I2: 25 | J2: =H2*I2 -> 850 | K2: =J2*0.478 -> 406.3 | L2: =J2-K2 -> 443.7 | M2: =IF(J2=0,0,L2/J2) -> 0.522 | N2: 4.7
A3: 2 | B3: يناير | C3: الأحد | D3: صباحي | E3: فرع مدينة نصر | F3: مشروبات | G3: عصير برتقال | H3: 73 | I3: 25 | J3: =H3*I3 -> 1825 | K3: =J3*0.356 -> 649.7 | L3: =J3-K3 -> 1175.3 | M3: =IF(J3=0,0,L3/J3) -> 0.644 | N3: 4.4
A4: 3 | B4: يناير | C4: الأحد | D4: صباحي | E4: فرع مدينة نصر | F4: مقبلات | G4: حمص | H4: 40 | I4: 30 | J4: =H4*I4 -> 1200 | K4: =J4*0.509 -> 610.8 | L4: =J4-K4 -> 589.2 | M4: =IF(J4=0,0,L4/J4) -> 0.491 | N4: 2.7
A5: 4 | B5: يناير | C5: الأحد | D5: مسائي | E5: فرع الزمالك | F5: وجبات سريعة | G5: رابتا | H5: 22 | I5: 45 | J5: =H5*I5 -> 990 | K5: =J5*0.397 -> 393.03 | L5: =J5-K5 -> 596.97 | M5: =IF(J5=0,0,L5/J5) -> 0.603 | N5: 3.4
A6: 5 | B6: يناير | C6: الخميس | D6: ليلي | E6: فرع الهرم | F6: مقبلات | G6: سلطة فتوش | H6: 51 | I6: 35 | J6: =H6*I6 -> 1785 | K6: =J6*0.373 -> 665.805 | L6: =J6-K6 -> 1119.195 | M6: =IF(J6=0,0,L6/J6) -> 0.627 | N6: 3.3
A7: 6 | B7: يناير | C7: الجمعة | D7: ليلي | E7: فرع الهرم | F7: حلويات | G7: تارت فراولة | H7: 75 | I7: 55 | J7: =H7*I7 -> 4125 | K7: =J7*0.438 -> 1806.75 | L7: =J7-K7 -> 2318.25 | M7: =IF(J7=0,0,L7/J7) -> 0.562 | N7: 5
A8: 7 | B8: يناير | C8: الثلاثاء | D8: صباحي | E8: فرع التجمع | F8: مقبلات | G8: بابا غنوج | H8: 42 | I8: 30 | J8: =H8*I8 -> 1260 | K8: =J8*0.401 -> 505.26 | L8: =J8-K8 -> 754.74 | M8: =IF(J8=0,0,L8/J8) -> 0.599 | N8: 3.8
A9: 8 | B9: يناير | C9: الثلاثاء | D9: ليلي | E9: فرع التجمع | F9: حلويات | G9: كنافة | H9: 55 | I9: 45 | J9: =H9*I9 -> 2475 | K9: =J9*0.397 -> 982.575 | L9: =J9-K9 -> 1492.425 | M9: =IF(J9=0,0,L9/J9) -> 0.603 | N9: 3.7
A10: 9 | B10: يناير | C10: الإثنين | D10: مسائي | E10: فرع مدينة نصر | F10: مشروبات | G10: عصير مانجو | H10: 21 | I10: 30 | J10: =H10*I10 -> 630 | K10: =J10*0.541 -> 340.83 | L10: =J10-K10 -> 289.17 | M10: =IF(J10=0,0,L10/J10) -> 0.459 | N10: 4.1
A11: 10 | B11: يناير | C11: الثلاثاء | D11: صباحي | E11: فرع التجمع | F11: وجبات رئيسية | G11: برجر لحم | H11: 10 | I11: 95 | J11: =H11*I11 -> 950 | K11: =J11*0.49 -> 465.5 | L11: =J11-K11 -> 484.5 | M11: =IF(J11=0,0,L11/J11) -> 0.51 | N11: 3.7
A12: 11 | B12: يناير | C12: السبت | D12: مسائي | E12: فرع التجمع | F12: حلويات | G12: بسبوسة | H12: 57 | I12: 25 | J12: =H12*I12 -> 1425 | K12: =J12*0.511 -> 728.175 | L12: =J12-K12 -> 696.825 | M12: =IF(J12=0,0,L12/J12) -> 0.489 | N12: 4.7
A13: 12 | B13: يناير | C13: السبت | D13: مسائي | E13: فرع مدينة نصر | F13: حلويات | G13: بسبوسة | H13: 35 | I13: 25 | J13: =H13*I13 -> 875 | K13: =J13*0.473 -> 413.875 | L13: =J13-K13 -> 461.125 | M13: =IF(J13=0,0,L13/J13) -> 0.527 | N13: 3
A14: 13 | B14: يناير | C14: الجمعة | D14: ليلي | E14: فرع الهرم | F14: مقبلات | G14: حمص | H14: 50 | I14: 30 | J14: =H14*I14 -> 1500 | K14: =J14*0.386 -> 579 | L14: =J14-K14 -> 921 | M14: =IF(J14=0,0,L14/J14) -> 0.614 | N14: 3.9
A15: 14 | B15: يناير | C15: الثلاثاء | D15: صباحي | E15: فرع مدينة نصر | F15: مشروبات | G15: عصير برتقال | H15: 33 | I15: 25 | J15: =H15*I15 -> 825 | K15: =J15*0.469 -> 386.925 | L15: =J15-K15 -> 438.075 | M15: =IF(J15=0,0,L15/J15) -> 0.531 | N15: 3.6
A16: 15 | B16: يناير | C16: السبت | D16: صباحي | E16: فرع الهرم | F16: وجبات رئيسية | G16: برجر لحم | H16: 48 | I16: 95 | J16: =H16*I16 -> 4560 | K16: =J16*0.375 -> 1710 | L16: =J16-K16 -> 2850 | M16: =IF(J16=0,0,L16/J16) -> 0.625 | N16: 3.8
A17: 16 | B17: يناير | C17: الأربعاء | D17: ليلي | E17: فرع الزمالك | F17: وجبات رئيسية | G17: برجر لحم | H17: 43 | I17: 95 | J17: =H17*I17 -> 4085 | K17: =J17*0.365 -> 1491.025 | L17: =J17-K17 -> 2593.975 | M17: =IF(J17=0,0,L17/J17) -> 0.635 | N17: 4
A18: 17 | B18: يناير | C18: الإثنين | D18: مسائي | E18: فرع التجمع | F18: مقبلات | G18: فتة | H18: 9 | I18: 50 | J18: =H18*I18 -> 450 | K18: =J18*0.449 -> 202.05 | L18: =J18-K18 -> 247.95 | M18: =IF(J18=0,0,L18/J18) -> 0.551 | N18: 3.3
A19: 18 | B19: يناير | C19: السبت | D19: صباحي | E19: فرع الهرم | F19: مقبلات | G19: سلطة فتوش | H19: 33 | I19: 35 | J19: =H19*I19 -> 1155 | K19: =J19*0.356 -> 411.18 | L19: =J19-K19 -> 743.82 | M19: =IF(J19=0,0,L19/J19) -> 0.644 | N19: 3.2
A20: 19 | B20: يناير | C20: الخميس | D20: ليلي | E20: فرع الهرم | F20: مشروبات | G20: كوكاكولا | H20: 38 | I20: 20 | J20: =H20*I20 -> 760 | K20: =J20*0.393 -> 298.68 | L20: =J20-K20 -> 461.32 | M20: =IF(J20=0,0,L20/J20) -> 0.607 | N20: 4.6
A21: 20 | B21: يناير | C21: الأحد | D21: صباحي | E21: فرع التجمع | F21: مقبلات | G21: بابا غنوج | H21: 50 | I21: 30 | J21: =H21*I21 -> 1500 | K21: =J21*0.436 -> 654 | L21: =J21-K21 -> 846 | M21: =IF(J21=0,0,L21/J21) -> 0.564 | N21: 4
A22: 21 | B22: فبراير | C22: الخميس | D22: مسائي | E22: فرع الزمالك | F22: وجبات سريعة | G22: بيتزا صغيرة | H22: 45 | I22: 70 | J22: =H22*I22 -> 3150 | K22: =J22*0.502 -> 1581.3 | L22: =J22-K22 -> 1568.7 | M22: =IF(J22=0,0,L22/J22) -> 0.498 | N22: 2.7
A23: 22 | B23: فبراير | C23: الخميس | D23: مسائي | E23: فرع الهرم | F23: وجبات رئيسية | G23: فراخ محشية | H23: 29 | I23: 130 | J23: =H23*I23 -> 3770 | K23: =J23*0.428 -> 1613.56 | L23: =J23-K23 -> 2156.44 | M23: =IF(J23=0,0,L23/J23) -> 0.572 | N23: 5
A24: 23 | B24: فبراير | C24: الثلاثاء | D24: صباحي | E24: فرع المعادي | F24: حلويات | G24: تارت فراولة | H24: 22 | I24: 55 | J24: =H24*I24 -> 1210 | K24: =J24*0.515 -> 623.15 | L24: =J24-K24 -> 586.85 | M24: =IF(J24=0,0,L24/J24) -> 0.485 | N24: 2.8
A25: 24 | B25: فبراير | C25: الأربعاء | D25: صباحي | E25: فرع مدينة نصر | F25: حلويات | G25: كنافة | H25: 54 | I25: 45 | J25: =H25*I25 -> 2430 | K25: =J25*0.37 -> 899.1 | L25: =J25-K25 -> 1530.9 | M25: =IF(J25=0,0,L25/J25) -> 0.63 | N25: 3.4
A26: 25 | B26: فبراير | C26: الأربعاء | D26: ليلي | E26: فرع التجمع | F26: وجبات سريعة | G26: رابتا | H26: 10 | I26: 45 | J26: =H26*I26 -> 450 | K26: =J26*0.544 -> 244.8 | L26: =J26-K26 -> 205.2 | M26: =IF(J26=0,0,L26/J26) -> 0.456 | N26: 3.2
A27: 26 | B27: فبراير | C27: السبت | D27: صباحي | E27: فرع المعادي | F27: حلويات | G27: بسبوسة | H27: 74 | I27: 25 | J27: =H27*I27 -> 1850 | K27: =J27*0.529 -> 978.65 | L27: =J27-K27 -> 871.35 | M27: =IF(J27=0,0,L27/J27) -> 0.471 | N27: 4.8
A28: 27 | B28: فبراير | C28: الإثنين | D28: مسائي | E28: فرع مدينة نصر | F28: وجبات رئيسية | G28: برجر لحم | H28: 52 | I28: 95 | J28: =H28*I28 -> 4940 | K28: =J28*0.514 -> 2539.16 | L28: =J28-K28 -> 2400.84 | M28: =IF(J28=0,0,L28/J28) -> 0.486 | N28: 3.2
A29: 28 | B29: فبراير | C29: الأحد | D29: مسائي | E29: فرع المعادي | F29: مشروبات | G29: كوكاكولا | H29: 71 | I29: 20 | J29: =H29*I29 -> 1420 | K29: =J29*0.429 -> 609.18 | L29: =J29-K29 -> 810.82 | M29: =IF(J29=0,0,L29/J29) -> 0.571 | N29: 3
A30: 29 | B30: فبراير | C30: الجمعة | D30: صباحي | E30: فرع المعادي | F30: مقبلات | G30: حمص | H30: 19 | I30: 30 | J30: =H30*I30 -> 570 | K30: =J30*0.502 -> 286.14 | L30: =J30-K30 -> 283.86 | M30: =IF(J30=0,0,L30/J30) -> 0.498 | N30: 4.9
A31: 30 | B31: فبراير | C31: الثلاثاء | D31: ليلي | E31: فرع الزمالك | F31: مقبلات | G31: سلطة فتوش | H31: 43 | I31: 35 | J31: =H31*I31 -> 1505 | K31: =J31*0.367 -> 552.335 | L31: =J31-K31 -> 952.665 | M31: =IF(J31=0,0,L31/J31) -> 0.633 | N31: 3.2
A32: 31 | B32: فبراير | C32: الإثنين | D32: ليلي | E32: فرع المعادي | F32: وجبات رئيسية | G32: كباب مشوي | H32: 6 | I32: 110 | J32: =H32*I32 -> 660 | K32: =J32*0.523 -> 345.18 | L32: =J32-K32 -> 314.82 | M32: =IF(J32=0,0,L32/J32) -> 0.477 | N32: 4.3
A33: 32 | B33: فبراير | C33: الأحد | D33: صباحي | E33: فرع الزمالك | F33: وجبات سريعة | G33: سندوتش كلوب | H33: 42 | I33: 55 | J33: =H33*I33 -> 2310 | K33: =J33*0.412 -> 951.72 | L33: =J33-K33 -> 1358.28 | M33: =IF(J33=0,0,L33/J33) -> 0.588 | N33: 2.8
A34: 33 | B34: فبراير | C34: الثلاثاء | D34: صباحي | E34: فرع التجمع | F34: وجبات سريعة | G34: رابتا | H34: 39 | I34: 45 | J34: =H34*I34 -> 1755 | K34: =J34*0.351 -> 616.005 | L34: =J34-K34 -> 1138.995 | M34: =IF(J34=0,0,L34/J34) -> 0.649 | N34: 3.6
A35: 34 | B35: فبراير | C35: الأربعاء | D35: صباحي | E35: فرع المعادي | F35: مقبلات | G35: فتة | H35: 40 | I35: 50 | J35: =H35*I35 -> 2000 | K35: =J35*0.399 -> 798 | L35: =J35-K35 -> 1202 | M35: =IF(J35=0,0,L35/J35) -> 0.601 | N35: 4.8
A36: 35 | B36: فبراير | C36: الخميس | D36: مسائي | E36: فرع الزمالك | F36: وجبات سريعة | G36: سندوتش كلوب | H36: 66 | I36: 55 | J36: =H36*I36 -> 3630 | K36: =J36*0.466 -> 1691.58 | L36: =J36-K36 -> 1938.42 | M36: =IF(J36=0,0,L36/J36) -> 0.534 | N36: 2.9
A37: 36 | B37: فبراير | C37: السبت | D37: مسائي | E37: فرع الهرم | F37: وجبات سريعة | G37: سندوتش كلوب | H37: 53 | I37: 55 | J37: =H37*I37 -> 2915 | K37: =J37*0.356 -> 1037.74 | L37: =J37-K37 -> 1877.26 | M37: =IF(J37=0,0,L37/J37) -> 0.644 | N37: 4.6
A38: 37 | B38: فبراير | C38: الإثنين | D38: صباحي | E38: فرع المعادي | F38: وجبات سريعة | G38: سندوتش كلوب | H38: 21 | I38: 55 | J38: =H38*I38 -> 1155 | K38: =J38*0.411 -> 474.705 | L38: =J38-K38 -> 680.295 | M38: =IF(J38=0,0,L38/J38) -> 0.589 | N38: 4
A39: 38 | B39: فبراير | C39: السبت | D39: ليلي | E39: فرع التجمع | F39: مقبلات | G39: حمص | H39: 32 | I39: 30 | J39: =H39*I39 -> 960 | K39: =J39*0.488 -> 468.48 | L39: =J39-K39 -> 491.52 | M39: =IF(J39=0,0,L39/J39) -> 0.512 | N39: 4.8
A40: 39 | B40: فبراير | C40: الأربعاء | D40: ليلي | E40: فرع المعادي | F40: مقبلات | G40: حمص | H40: 23 | I40: 30 | J40: =H40*I40 -> 690 | K40: =J40*0.361 -> 249.09 | L40: =J40-K40 -> 440.91 | M40: =IF(J40=0,0,L40/J40) -> 0.639 | N40: 2.9
...

Sheet 📊 Dashboard
A1: 🍽️ لوحة تحليل أداء المطاعم — 2025
A3: تحليل شامل لـ 5 فروع | 240 معاملة | المبيعات — الأرباح — التصنيفات — الخدمة
A5: 🍽️ إجمالي المبيعات | D5: 💰 إجمالي الأرباح | G5: ⭐ متوسط تقييم الخدمة | J5: 📊 متوسط هامش الربح
A6: =SUM('📋 Raw Data'!J2:J241) -> 519220 | D6: =SUM('📋 Raw Data'!L2:L241) -> 287954.27 | G6: =AVERAGE('📋 Raw Data'!N2:N241) -> 3.7470833 | J6: =AVERAGE('📋 Raw Data'!M2:M241) -> 0.55406667
A9: 🏪 أداء الفروع | F9: 🍕 أداء التصنيفات
A10: الفرع | B10: المبيعات (ج.م) | C10: الأرباح (ج.م) | D10: متوسط التقييم | F10: التصنيف | G10: المبيعات (ج.م) | H10: الأرباح (ج.م) | I10: هامش الربح %
A11: فرع المعادي | B11: =SUMIF('📋 Raw Data'!E$2:E$241,A11,'📋 Raw Data'!J$2:J$241) -> 89960 | C11: =SUMIF('📋 Raw Data'!E$2:E$241,A11,'📋 Raw Data'!L$2:L$241) -> 50021.69 | D11: =AVERAGEIF('📋 Raw Data'!E$2:E$241,A11,'📋 Raw Data'!N$2:N$241) -> 3.6877551 | F11: وجبات رئيسية | G11: =SUMIF('📋 Raw Data'!F$2:F$241,F11,'📋 Raw Data'!J$2:J$241) -> 193110 | H11: =SUMIF('📋 Raw Data'!F$2:F$241,F11,'📋 Raw Data'!L$2:L$241) -> 105735.09 | I11: =IF(G11=0,0,H11/G11) -> 0.54753811
A12: فرع مدينة نصر | B12: =SUMIF('📋 Raw Data'!E$2:E$241,A12,'📋 Raw Data'!J$2:J$241) -> 114485 | C12: =SUMIF('📋 Raw Data'!E$2:E$241,A12,'📋 Raw Data'!L$2:L$241) -> 63410.16 | D12: =AVERAGEIF('📋 Raw Data'!E$2:E$241,A12,'📋 Raw Data'!N$2:N$241) -> 3.9384615 | F12: مشروبات | G12: =SUMIF('📋 Raw Data'!F$2:F$241,F12,'📋 Raw Data'!J$2:J$241) -> 59520 | H12: =SUMIF('📋 Raw Data'!F$2:F$241,F12,'📋 Raw Data'!L$2:L$241) -> 31652.025 | I12: =IF(G12=0,0,H12/G12) -> 0.53178805
A13: فرع الزمالك | B13: =SUMIF('📋 Raw Data'!E$2:E$241,A13,'📋 Raw Data'!J$2:J$241) -> 124680 | C13: =SUMIF('📋 Raw Data'!E$2:E$241,A13,'📋 Raw Data'!L$2:L$241) -> 68677.635 | D13: =AVERAGEIF('📋 Raw Data'!E$2:E$241,A13,'📋 Raw Data'!N$2:N$241) -> 3.5644444 | F13: حلويات | G13: =SUMIF('📋 Raw Data'!F$2:F$241,F13,'📋 Raw Data'!J$2:J$241) -> 85035 | H13: =SUMIF('📋 Raw Data'!F$2:F$241,F13,'📋 Raw Data'!L$2:L$241) -> 47329.905 | I13: =IF(G13=0,0,H13/G13) -> 0.55659323
A14: فرع التجمع | B14: =SUMIF('📋 Raw Data'!E$2:E$241,A14,'📋 Raw Data'!J$2:J$241) -> 84570 | C14: =SUMIF('📋 Raw Data'!E$2:E$241,A14,'📋 Raw Data'!L$2:L$241) -> 47666.67 | D14: =AVERAGEIF('📋 Raw Data'!E$2:E$241,A14,'📋 Raw Data'!N$2:N$241) -> 3.8090909 | F14: وجبات سريعة | G14: =SUMIF('📋 Raw Data'!F$2:F$241,F14,'📋 Raw Data'!J$2:J$241) -> 122220 | H14: =SUMIF('📋 Raw Data'!F$2:F$241,F14,'📋 Raw Data'!L$2:L$241) -> 69142.075 | I14: =IF(G14=0,0,H14/G14) -> 0.56571817
A15: فرع الهرم | B15: =SUMIF('📋 Raw Data'!E$2:E$241,A15,'📋 Raw Data'!J$2:J$241) -> 105525 | C15: =SUMIF('📋 Raw Data'!E$2:E$241,A15,'📋 Raw Data'!L$2:L$241) -> 58178.115 | D15: =AVERAGEIF('📋 Raw Data'!E$2:E$241,A15,'📋 Raw Data'!N$2:N$241) -> 3.716 | F15: مقبلات | G15: =SUMIF('📋 Raw Data'!F$2:F$241,F15,'📋 Raw Data'!J$2:J$241) -> 59335 | H15: =SUMIF('📋 Raw Data'!F$2:F$241,F15,'📋 Raw Data'!L$2:L$241) -> 34095.18 | I15: =IF(G15=0,0,H15/G15) -> 0.57462172
A19: 📅 الأداء الشهري | F19: ⏰ أداء الورديات
A20: الشهر | B20: المبيعات (ج.م) | C20: الأرباح (ج.م) | D20: هامش الربح % | F20: الوردية | G20: المبيعات (ج.م) | H20: الأرباح (ج.م) | I20: متوسط التقييم
A21: يناير | B21: =SUMPRODUCT(('📋 Raw Data'!B$2:B$241=A21)*'📋 Raw Data'!J$2:J$241) -> 33225 | C21: =SUMPRODUCT(('📋 Raw Data'!B$2:B$241=A21)*'📋 Raw Data'!L$2:L$241) -> 19523.54 | D21: =IF(B21=0,0,C21/B21) -> 0.58761595 | F21: صباحي | G21: =SUMIF('📋 Raw Data'!D$2:D$241,F21,'📋 Raw Data'!J$2:J$241) -> 177320 | H21: =SUMIF('📋 Raw Data'!D$2:D$241,F21,'📋 Raw Data'!L$2:L$241) -> 99693.07 | I21: =AVERAGEIF('📋 Raw Data'!D$2:D$241,F21,'📋 Raw Data'!N$2:N$241) -> 3.7141176
A22: فبراير | B22: =SUMPRODUCT(('📋 Raw Data'!B$2:B$241=A22)*'📋 Raw Data'!J$2:J$241) -> 38525 | C22: =SUMPRODUCT(('📋 Raw Data'!B$2:B$241=A22)*'📋 Raw Data'!L$2:L$241) -> 21504.28 | D22: =IF(B22=0,0,C22/B22) -> 0.55819027 | F22: مسائي | G22: =SUMIF('📋 Raw Data'!D$2:D$241,F22,'📋 Raw Data'!J$2:J$241) -> 153260 | H22: =SUMIF('📋 Raw Data'!D$2:D$241,F22,'📋 Raw Data'!L$2:L$241) -> 83640.925 | I22: =AVERAGEIF('📋 Raw Data'!D$2:D$241,F22,'📋 Raw Data'!N$2:N$241) -> 3.7582278
A23: مارس | B23: =SUMPRODUCT(('📋 Raw Data'!B$2:B$241=A23)*'📋 Raw Data'!J$2:J$241) -> 46790 | C23: =SUMPRODUCT(('📋 Raw Data'!B$2:B$241=A23)*'📋 Raw Data'!L$2:L$241) -> 24871.435 | D23: =IF(B23=0,0,C23/B23) -> 0.5315545 | F23: ليلي | G23: =SUMIF('📋 Raw Data'!D$2:D$241,F23,'📋 Raw Data'!J$2:J$241) -> 188640 | H23: =SUMIF('📋 Raw Data'!D$2:D$241,F23,'📋 Raw Data'!L$2:L$241) -> 104620.27 | I23: =AVERAGEIF('📋 Raw Data'!D$2:D$241,F23,'📋 Raw Data'!N$2:N$241) -> 3.7723684
A24: أبريل | B24: =SUMPRODUCT(('📋 Raw Data'!B$2:B$241=A24)*'📋 Raw Data'!J$2:J$241) -> 42895 | C24: =SUMPRODUCT(('📋 Raw Data'!B$2:B$241=A24)*'📋 Raw Data'!L$2:L$241) -> 24632.595 | D24: =IF(B24=0,0,C24/B24) -> 0.57425329
A25: مايو | B25: =SUMPRODUCT(('📋 Raw Data'!B$2:B$241=A25)*'📋 Raw Data'!J$2:J$241) -> 53525 | C25: =SUMPRODUCT(('📋 Raw Data'!B$2:B$241=A25)*'📋 Raw Data'!L$2:L$241) -> 30717.155 | D25: =IF(B25=0,0,C25/B25) -> 0.57388426
A26: يونيو | B26: =SUMPRODUCT(('📋 Raw Data'!B$2:B$241=A26)*'📋 Raw Data'!J$2:J$241) -> 48295 | C26: =SUMPRODUCT(('📋 Raw Data'!B$2:B$241=A26)*'📋 Raw Data'!L$2:L$241) -> 27825.95 | D26: =IF(B26=0,0,C26/B26) -> 0.57616627
A27: يوليو | B27: =SUMPRODUCT(('📋 Raw Data'!B$2:B$241=A27)*'📋 Raw Data'!J$2:J$241) -> 28855 | C27: =SUMPRODUCT(('📋 Raw Data'!B$2:B$241=A27)*'📋 Raw Data'!L$2:L$241) -> 16303.04 | D27: =IF(B27=0,0,C27/B27) -> 0.56499879
A28: أغسطس | B28: =SUMPRODUCT(('📋 Raw Data'!B$2:B$241=A28)*'📋 Raw Data'!J$2:J$241) -> 47605 | C28: =SUMPRODUCT(('📋 Raw Data'!B$2:B$241=A28)*'📋 Raw Data'!L$2:L$241) -> 26147.47 | D28: =IF(B28=0,0,C28/B28) -> 0.5492589
A29: سبتمبر | B29: =SUMPRODUCT(('📋 Raw Data'!B$2:B$241=A29)*'📋 Raw Data'!J$2:J$241) -> 28860 | C29: =SUMPRODUCT(('📋 Raw Data'!B$2:B$241=A29)*'📋 Raw Data'!L$2:L$241) -> 15940.48 | D29: =IF(B29=0,0,C29/B29) -> 0.55233818
A30: أكتوبر | B30: =SUMPRODUCT(('📋 Raw Data'!B$2:B$241=A30)*'📋 Raw Data'!J$2:J$241) -> 59005 | C30: =SUMPRODUCT(('📋 Raw Data'!B$2:B$241=A30)*'📋 Raw Data'!L$2:L$241) -> 31575.075 | D30: =IF(B30=0,0,C30/B30) -> 0.53512541
A31: نوفمبر | B31: =SUMPRODUCT(('📋 Raw Data'!B$2:B$241=A31)*'📋 Raw Data'!J$2:J$241) -> 49030 | C31: =SUMPRODUCT(('📋 Raw Data'!B$2:B$241=A31)*'📋 Raw Data'!L$2:L$241) -> 26289 | D31: =IF(B31=0,0,C31/B31) -> 0.53618193
A32: ديسمبر | B32: =SUMPRODUCT(('📋 Raw Data'!B$2:B$241=A32)*'📋 Raw Data'!J$2:J$241) -> 42610 | C32: =SUMPRODUCT(('📋 Raw Data'!B$2:B$241=A32)*'📋 Raw Data'!L$2:L$241) -> 22624.25 | D32: =IF(B32=0,0,C32/B32) -> 0.53096104
